Workbook
Name UPDATE: 'Data Sheet'!$E$1

Sheet Profit & Loss
A1: ='Data Sheet'!B1 -> ADANI POWER LTD | H1: =UPDATE | M1: SCREENER.IN
A3: Narration | B3: ='Data Sheet'!B16 -> 42460 | C3: ='Data Sheet'!C16 -> 42825 | D3: ='Data Sheet'!D16 -> 43190 | E3: ='Data Sheet'!E16 -> 43555 | F3: ='Data Sheet'!F16 -> 43921 | G3: ='Data Sheet'!G16 -> 44286 | H3: ='Data Sheet'!H16 -> 44651 | I3: ='Data Sheet'!I16 -> 45016 | ... K3: ='Data Sheet'!K16 -> 45747 | L3: Trailing | M3: Best Case | N3: Worst Case
A4: Sales | B4: ='Data Sheet'!B17 -> 25377.33 | C4: ='Data Sheet'!C17 -> 22615.51 | D4: ='Data Sheet'!D17 -> 20304.28 | E4: ='Data Sheet'!E17 -> 23884.18 | F4: ='Data Sheet'!F17 -> 26467.72 | G4: ='Data Sheet'!G17 -> 26221.48 | H4: ='Data Sheet'!H17 -> 27711.18 | I4: ='Data Sheet'!I17 -> 38773.3 | ... K4: ='Data Sheet'!K17 -> 56203.09 | L4: =SUM(Quarters!H4:K4) -> 54254.83 | M4: =$K4+M23*K4 -> 71142.412 | N4: =$K4+N23*L4 -> 61214.402
A5: Expenses | B5: =SUM('Data Sheet'!B18,'Data Sheet'!B20:B24, -1*'Data Sheet'!B19) -> 16575.2 | C5: =SUM('Data Sheet'!C18,'Data Sheet'!C20:C24, -1*'Data Sheet'!C19) -> 16635.47 | D5: =SUM('Data Sheet'!D18,'Data Sheet'!D20:D24, -1*'Data Sheet'!D19) -> 14868.35 | E5: =SUM('Data Sheet'!E18,'Data Sheet'!E20:E24, -1*'Data Sheet'!E19) -> 18900.77 | F5: =SUM('Data Sheet'!F18,'Data Sheet'!F20:F24, -1*'Data Sheet'!F19) -> 20734.08 | G5: =SUM('Data Sheet'!G18,'Data Sheet'!G20:G24, -1*'Data Sheet'!G19) -> 17533.32 | H5: =SUM('Data Sheet'!H18,'Data Sheet'!H20:H24, -1*'Data Sheet'!H19) -> 17829.77 | I5: =SUM('Data Sheet'!I18,'Data Sheet'!I20:I24, -1*'Data Sheet'!I19) -> 28676.96 | ... K5: =SUM('Data Sheet'!K18,'Data Sheet'!K20:K24, -1*'Data Sheet'!K19) -> 34784.76 | L5: =SUM(Quarters!H5:K5) -> 34368.56 | M5: =M4-M6 -> 45066.26 | N5: =N4-N6 -> 42104.09
A6: Operating Profit | B6: =B4-B5 -> 8802.13 | C6: =C4-C5 -> 5980.04 | D6: =D4-D5 -> 5435.93 | E6: =E4-E5 -> 4983.41 | F6: =F4-F5 -> 5733.64 | G6: =G4-G5 -> 8688.16 | H6: =H4-H5 -> 9881.41 | I6: =I4-I5 -> 10096.34 | ... K6: =K4-K5 -> 21418.33 | L6: =SUM(Quarters!H6:K6) -> 19886.27 | M6: =M4*M24 -> 26076.152 | N6: =N4*N24 -> 19110.312
A7: Other Income | B7: ='Data Sheet'!B25 -> -201.37 | C7: ='Data Sheet'!C25 -> -3666.12 | D7: ='Data Sheet'!D25 -> 754.1 | E7: ='Data Sheet'!E25 -> 2447.87 | F7: ='Data Sheet'!F25 -> 322.76 | G7: ='Data Sheet'!G25 -> 1908.56 | H7: ='Data Sheet'!H25 -> 3908.04 | I7: ='Data Sheet'!I25 -> 4215.54 | ... K7: ='Data Sheet'!K25 -> 2589.85 | L7: =SUM(Quarters!H7:K7) -> 2156.96 | M7: 0 | N7: 0
A8: Depreciation | B8: ='Data Sheet'!B26 -> 2665.82 | C8: ='Data Sheet'!C26 -> 2672.36 | D8: ='Data Sheet'!D26 -> 2698.72 | E8: ='Data Sheet'!E26 -> 2750.62 | F8: ='Data Sheet'!F26 -> 3006.5 | G8: ='Data Sheet'!G26 -> 3201.65 | H8: ='Data Sheet'!H26 -> 3117.54 | I8: ='Data Sheet'!I26 -> 3303.68 | ... K8: ='Data Sheet'!K26 -> 4308.88 | L8: =SUM(Quarters!H8:K8) -> 4501.95 | M8: =+$L8 -> 4501.95 | N8: =+$L8 -> 4501.95
A9: Interest | B9: ='Data Sheet'!B27 -> 5560.22 | C9: ='Data Sheet'!C27 -> 5901.73 | D9: ='Data Sheet'!D27 -> 5570.23 | E9: ='Data Sheet'!E27 -> 5656.52 | F9: ='Data Sheet'!F27 -> 5314.82 | G9: ='Data Sheet'!G27 -> 5106.33 | H9: ='Data Sheet'!H27 -> 4094.78 | I9: ='Data Sheet'!I27 -> 3333.5 | ... K9: ='Data Sheet'!K27 -> 3339.79 | L9: =SUM(Quarters!H9:K9) -> 3164.47 | M9: =+$L9 -> 3164.47 | N9: =+$L9 -> 3164.47
A10: Profit before tax | B10: ='Data Sheet'!B28 -> 374.72 | C10: ='Data Sheet'!C28 -> -6260.17 | D10: ='Data Sheet'!D28 -> -2078.92 | E10: ='Data Sheet'!E28 -> -975.86 | F10: ='Data Sheet'!F28 -> -2264.92 | G10: ='Data Sheet'!G28 -> 2288.74 | H10: ='Data Sheet'!H28 -> 6577.13 | I10: ='Data Sheet'!I28 -> 7674.7 | ... K10: ='Data Sheet'!K28 -> 16359.51 | L10: =SUM(Quarters!H10:K10) -> 14376.81 | M10: =M6+M7-SUM(M8:M9) -> 18409.732 | N10: =N6+N7-SUM(N8:N9) -> 11443.892
A11: Tax | B11: ='Data Sheet'!B29 -> -176.08 | C11: ='Data Sheet'!C29 -> -86.07 | D11: ='Data Sheet'!D29 -> -5.15 | E11: ='Data Sheet'!E29 -> 8.54 | F11: ='Data Sheet'!F29 -> 9.85 | G11: ='Data Sheet'!G29 -> 1018.76 | H11: ='Data Sheet'!H29 -> 1665.55 | I11: ='Data Sheet'!I29 -> -3051.94 | ... K11: ='Data Sheet'!K29 -> 3609.9 | L11: =SUM(Quarters!H11:K11) -> 3077.9 | M11: =IF($L10>0,$L11/$L10,0) -> 0.21408783 | N11: =IF($L10>0,$L11/$L10,0) -> 0.21408783
A12: Net profit | B12: ='Data Sheet'!B30 -> 550.8 | C12: ='Data Sheet'!C30 -> -6174.1 | D12: ='Data Sheet'!D30 -> -2102.95 | E12: ='Data Sheet'!E30 -> -984.4 | F12: ='Data Sheet'!F30 -> -2274.77 | G12: ='Data Sheet'!G30 -> 1269.98 | H12: ='Data Sheet'!H30 -> 4911.58 | I12: ='Data Sheet'!I30 -> 10726.64 | ... K12: ='Data Sheet'!K30 -> 12938.77 | L12: =SUM(Quarters!H12:K12) -> 11454.19 | M12: =M10-M11*M10 -> 14468.433 | N12: =N10-N11*N10 -> 8993.8943
A13: EPS | B13: =IF('Data Sheet'!B93>0,B12/'Data Sheet'!B93,0) -> 0.33041986 | C13: =IF('Data Sheet'!C93>0,C12/'Data Sheet'!C93,0) -> -3.2015536 | D13: =IF('Data Sheet'!D93>0,D12/'Data Sheet'!D93,0) -> -1.0904759 | E13: =IF('Data Sheet'!E93>0,E12/'Data Sheet'!E93,0) -> -0.51045648 | F13: =IF('Data Sheet'!F93>0,F12/'Data Sheet'!F93,0) -> -1.1795724 | G13: =IF('Data Sheet'!G93>0,G12/'Data Sheet'!G93,0) -> 0.65854278 | H13: =IF('Data Sheet'!H93>0,H12/'Data Sheet'!H93,0) -> 2.5468791 | I13: =IF('Data Sheet'!I93>0,I12/'Data Sheet'!I93,0) -> 5.562254 | ... K13: =IF('Data Sheet'!K93>0,K12/'Data Sheet'!K93,0) -> 6.7093447 | L13: =IF('Data Sheet'!$B6>0,'Profit & Loss'!L12/'Data Sheet'!$B6,0) -> 5.9395236 | M13: =IF('Data Sheet'!$B6>0,'Profit & Loss'!M12/'Data Sheet'!$B6,0) -> 7.502547 | N13: =IF('Data Sheet'!$B6>0,'Profit & Loss'!N12/'Data Sheet'!$B6,0) -> 4.6637473
A14: Price to earning | B14: =IF(B15>0,B15/B13,"") -> 20.852257 | C14: =IF(C15>0,C15/C13,"") -> -2.4925399 | D14: =IF(D15>0,D15/D13,"") -> -4.3467262 | E14: =IF(E15>0,E15/E13,"") -> -18.885058 | F14: =IF(F15>0,F15/F13,"") -> -4.7050948 | G14: =IF(G15>0,G15/G13,"") -> 25.829757 | H14: =IF(H15>0,H15/H13,"") -> 14.535437 | I14: =IF(I15>0,I15/I13,"") -> 6.8892934 | ... K14: =IF(K15>0,K15/K13,"") -> 15.18181 | L14: =IF(L13>0,L15/L13,0) -> 33.420189 | M14: =M25 -> 33.420189 | N14: =N25 -> 16.343964
A15: Price | B15: ='Data Sheet'!B90 -> 6.89 | C15: ='Data Sheet'!C90 -> 7.98 | D15: ='Data Sheet'!D90 -> 4.74 | E15: ='Data Sheet'!E90 -> 9.64 | F15: ='Data Sheet'!F90 -> 5.55 | G15: ='Data Sheet'!G90 -> 17.01 | H15: ='Data Sheet'!H90 -> 37.02 | I15: ='Data Sheet'!I90 -> 38.32 | ... K15: ='Data Sheet'!K90 -> 101.86 | L15: ='Data Sheet'!B8 -> 198.5 | M15: =M13*M14 -> 250.73653 | N15: =N13*N14 -> 76.224116
A17: RATIOS:
A18: Dividend Payout | B18: =IF('Data Sheet'!B30>0, 'Data Sheet'!B31/'Data Sheet'!B30, 0) -> 0 | C18: =IF('Data Sheet'!C30>0, 'Data Sheet'!C31/'Data Sheet'!C30, 0) -> 0 | D18: =IF('Data Sheet'!D30>0, 'Data Sheet'!D31/'Data Sheet'!D30, 0) -> 0 | E18: =IF('Data Sheet'!E30>0, 'Data Sheet'!E31/'Data Sheet'!E30, 0) -> 0 | F18: =IF('Data Sheet'!F30>0, 'Data Sheet'!F31/'Data Sheet'!F30, 0) -> 0 | G18: =IF('Data Sheet'!G30>0, 'Data Sheet'!G31/'Data Sheet'!G30, 0) -> 0 | H18: =IF('Data Sheet'!H30>0, 'Data Sheet'!H31/'Data Sheet'!H30, 0) -> 0 | I18: =IF('Data Sheet'!I30>0, 'Data Sheet'!I31/'Data Sheet'!I30, 0) -> 0 | ... K18: =IF('Data Sheet'!K30>0, 'Data Sheet'!K31/'Data Sheet'!K30, 0) -> 0
A19: OPM | B19: =IF(B6>0,B6/B4,0) -> 0.34685012 | C19: =IF(C6>0,C6/C4,0) -> 0.26442207 | D19: =IF(D6>0,D6/D4,0) -> 0.26772336 | E19: =IF(E6>0,E6/E4,0) -> 0.20864899 | F19: =IF(F6>0,F6/F4,0) -> 0.21662765 | G19: =IF(G6>0,G6/G4,0) -> 0.33133751 | H19: =IF(H6>0,H6/H4,0) -> 0.35658568 | I19: =IF(I6>0,I6/I4,0) -> 0.26039414 | ... L19: =IF(L6>0,L6/L4,0) -> 0.36653456
G22: TRENDS: | H22: 10 YEARS | I22: 7 YEARS | J22: 5 YEARS | K22: 3 YEARS | L22: RECENT | M22: BEST | N22: WORST
G23: Sales Growth | H23: =IF(B4=0,"",POWER($K4/B4,1/9)-1) -> 0.092366195 | I23: =IF(D4=0,"",POWER($K4/D4,1/7)-1) -> 0.15655826 | J23: =IF(F4=0,"",POWER($K4/F4,1/5)-1) -> 0.16254222 | K23: =IF(H4=0,"",POWER($K4/H4, 1/3)-1) -> 0.26580962 | L23: =IF(ISERROR(MAX(IF(J4=0,"",(K4-J4)/J4),IF(K4=0,"",(L4-K4)/K4))),"",MAX(IF(J4=0,"",(K4-J4)/J4),IF(K4=0,"",(L4-K4)/K4))) -> 0.11622035 | M23: =MAX(K23:L23) -> 0.26580962 | N23: =MIN(H23:L23) -> 0.092366195
G24: OPM | H24: =IF(SUM(B4:$K$4)=0,"",SUMPRODUCT(B19:$K$19,B4:$K$4)/SUM(B4:$K$4)) -> 0.31218654 | I24: =IF(SUM(E4:$K$4)=0,"",SUMPRODUCT(E19:$K$19,E4:$K$4)/SUM(E4:$K$4)) -> 0.31660676 | J24: =IF(SUM(G4:$K$4)=0,"",SUMPRODUCT(G19:$K$19,G4:$K$4)/SUM(G4:$K$4)) -> 0.34282725 | K24: =IF(SUM(I4:$K$4)=0, "", SUMPRODUCT(I19:$K$19,I4:$K$4)/SUM(I4:$K$4)) -> 0.34227687 | L24: =L19 -> 0.36653456 | M24: =MAX(K24:L24) -> 0.36653456 | N24: =MIN(H24:L24) -> 0.31218654
G25: Price to Earning | H25: =IF(ISERROR(AVERAGEIF(B14:$L14,">0")),"",AVERAGEIF(B14:$L14,">0")) -> 18.084758 | I25: =IF(ISERROR(AVERAGEIF(E14:$L14,">0")),"",AVERAGEIF(E14:$L14,">0")) -> 17.623508 | J25: =IF(ISERROR(AVERAGEIF(G14:$L14,">0")),"",AVERAGEIF(G14:$L14,">0")) -> 17.623508 | K25: =IF(ISERROR(AVERAGEIF(I14:$L14,">0")),"",AVERAGEIF(I14:$L14,">0")) -> 16.343964 | L25: =L14 -> 33.420189 | M25: =MAX(K25:L25) -> 33.420189 | N25: =MIN(H25:L25) -> 16.343964

Sheet Quarters
A1: ='Profit & Loss'!A1 -> ADANI POWER LTD | E1: =UPDATE | J1: SCREENER.IN
A3: Narration | B3: ='Data Sheet'!B41 -> 45199 | C3: ='Data Sheet'!C41 -> 45291 | D3: ='Data Sheet'!D41 -> 45382 | E3: ='Data Sheet'!E41 -> 45473 | F3: ='Data Sheet'!F41 -> 45565 | G3: ='Data Sheet'!G41 -> 45657 | H3: ='Data Sheet'!H41 -> 45747 | I3: ='Data Sheet'!I41 -> 45838 | ... K3: ='Data Sheet'!K41 -> 46022
A4: Sales | B4: ='Data Sheet'!B42 -> 12990.58 | C4: ='Data Sheet'!C42 -> 12991.44 | D4: ='Data Sheet'!D42 -> 13363.69 | E4: ='Data Sheet'!E42 -> 14955.63 | F4: ='Data Sheet'!F42 -> 13338.88 | G4: ='Data Sheet'!G42 -> 13671.18 | H4: ='Data Sheet'!H42 -> 14237.4 | I4: ='Data Sheet'!I42 -> 14109.15 | ... K4: ='Data Sheet'!K42 -> 12451.44
A5: Expenses | B5: ='Data Sheet'!B43 -> 7819.19 | C5: ='Data Sheet'!C43 -> 8346.1 | D5: ='Data Sheet'!D43 -> 8513.95 | E5: ='Data Sheet'!E43 -> 8761.32 | F5: ='Data Sheet'!F43 -> 8063.3 | G5: ='Data Sheet'!G43 -> 8648.26 | H5: ='Data Sheet'!H43 -> 9424.77 | I5: ='Data Sheet'!I43 -> 8423.87 | ... K5: ='Data Sheet'!K43 -> 8213.37
A6: Operating Profit | B6: ='Data Sheet'!B50 -> 5171.39 | C6: ='Data Sheet'!C50 -> 4645.34 | D6: ='Data Sheet'!D50 -> 4849.74 | E6: ='Data Sheet'!E50 -> 6194.31 | F6: ='Data Sheet'!F50 -> 5275.58 | G6: ='Data Sheet'!G50 -> 5022.92 | H6: ='Data Sheet'!H50 -> 4812.63 | I6: ='Data Sheet'!I50 -> 5685.28 | ... K6: ='Data Sheet'!K50 -> 4238.07
A7: Other Income | B7: ='Data Sheet'!B44 -> 1945.1 | C7: ='Data Sheet'!C44 -> 363.83 | D7: ='Data Sheet'!D44 -> 517.83 | E7: ='Data Sheet'!E44 -> 518.32 | F7: ='Data Sheet'!F44 -> 723.96 | G7: ='Data Sheet'!G44 -> 1162.26 | H7: ='Data Sheet'!H44 -> 298.2 | I7: ='Data Sheet'!I44 -> 464.55 | ... K7: ='Data Sheet'!K44 -> 543.26
A8: Depreciation | B8: ='Data Sheet'!B45 -> 1004.48 | C8: ='Data Sheet'!C45 -> 1002.23 | D8: ='Data Sheet'!D45 -> 990.03 | E8: ='Data Sheet'!E45 -> 995.63 | F8: ='Data Sheet'!F45 -> 1058.59 | G8: ='Data Sheet'!G45 -> 1170.01 | H8: ='Data Sheet'!H45 -> 1084.65 | I8: ='Data Sheet'!I45 -> 1088.59 | ... K8: ='Data Sheet'!K45 -> 1135.3
A9: Interest | B9: ='Data Sheet'!B46 -> 888.44 | C9: ='Data Sheet'!C46 -> 796.56 | D9: ='Data Sheet'!D46 -> 819.6 | E9: ='Data Sheet'!E46 -> 811.49 | F9: ='Data Sheet'!F46 -> 806.87 | G9: ='Data Sheet'!G46 -> 956.53 | H9: ='Data Sheet'!H46 -> 764.9 | I9: ='Data Sheet'!I46 -> 856.93 | ... K9: ='Data Sheet'!K46 -> 701.01
A10: Profit before tax | B10: ='Data Sheet'!B47 -> 5223.57 | C10: ='Data Sheet'!C47 -> 3210.38 | D10: ='Data Sheet'!D47 -> 3557.94 | E10: ='Data Sheet'!E47 -> 4905.51 | F10: ='Data Sheet'!F47 -> 4134.08 | G10: ='Data Sheet'!G47 -> 4058.64 | H10: ='Data Sheet'!H47 -> 3261.28 | I10: ='Data Sheet'!I47 -> 4204.31 | ... K10: ='Data Sheet'!K47 -> 2945.02
A11: Tax | B11: ='Data Sheet'!B48 -> -1370.6 | C11: ='Data Sheet'!C48 -> 472.42 | D11: ='Data Sheet'!D48 -> 820.7 | E11: ='Data Sheet'!E48 -> 992.72 | F11: ='Data Sheet'!F48 -> 836.56 | G11: ='Data Sheet'!G48 -> 1118.57 | H11: ='Data Sheet'!H48 -> 662.05 | I11: ='Data Sheet'!I48 -> 899.18 | ... K11: ='Data Sheet'!K48 -> 456.93
A12: Net profit | B12: ='Data Sheet'!B49 -> 6594.17 | C12: ='Data Sheet'!C49 -> 2737.96 | D12: ='Data Sheet'!D49 -> 2737.24 | E12: ='Data Sheet'!E49 -> 3912.79 | F12: ='Data Sheet'!F49 -> 3331.8 | G12: ='Data Sheet'!G49 -> 3057.21 | H12: ='Data Sheet'!H49 -> 2636.97 | I12: ='Data Sheet'!I49 -> 3384.86 | ... K12: ='Data Sheet'!K49 -> 2479.58
A14: OPM | B14: =IF(B4>0,B6/B4,"") -> 0.39808769 | C14: =IF(C4>0,C6/C4,"") -> 0.35756929 | D14: =IF(D4>0,D6/D4,"") -> 0.36290426 | E14: =IF(E4>0,E6/E4,"") -> 0.41417914 | F14: =IF(F4>0,F6/F4,"") -> 0.39550397 | G14: =IF(G4>0,G6/G4,"") -> 0.3674094 | H14: =IF(H4>0,H6/H4,"") -> 0.33802731 | I14: =IF(I4>0,I6/I4,"") -> 0.40294986 | ... K14: =IF(K4>0,K6/K4,"") -> 0.34036786

Sheet Balance Sheet
A1: ='Profit & Loss'!A1 -> ADANI POWER LTD | E1: =UPDATE | J1: SCREENER.IN
A3: Narration | B3: ='Data Sheet'!B56 -> 42460 | C3: ='Data Sheet'!C56 -> 42825 | D3: ='Data Sheet'!D56 -> 43190 | E3: ='Data Sheet'!E56 -> 43555 | F3: ='Data Sheet'!F56 -> 43921 | G3: ='Data Sheet'!G56 -> 44286 | H3: ='Data Sheet'!H56 -> 44651 | I3: ='Data Sheet'!I56 -> 45016 | ... K3: ='Data Sheet'!K56 -> 45747
A4: Equity Share Capital | B4: ='Data Sheet'!B57 -> 3333.94 | C4: ='Data Sheet'!C57 -> 3856.94 | D4: ='Data Sheet'!D57 -> 3856.94 | E4: ='Data Sheet'!E57 -> 3856.94 | F4: ='Data Sheet'!F57 -> 3856.94 | G4: ='Data Sheet'!G57 -> 3856.94 | H4: ='Data Sheet'!H57 -> 3856.94 | I4: ='Data Sheet'!I57 -> 3856.94 | ... K4: ='Data Sheet'!K57 -> 3856.94
A5: Reserves | B5: ='Data Sheet'!B58 -> 4133.92 | C5: ='Data Sheet'!C58 -> -857.38 | D5: ='Data Sheet'!D58 -> -2967.61 | E5: ='Data Sheet'!E58 -> 3855.35 | F5: ='Data Sheet'!F58 -> 2623.5 | G5: ='Data Sheet'!G58 -> 9255.65 | H5: ='Data Sheet'!H58 -> 14599.95 | I5: ='Data Sheet'!I58 -> 26018.72 | ... K5: ='Data Sheet'!K58 -> 52490.15
A6: Borrowings | B6: ='Data Sheet'!B59 -> 52729.32 | C6: ='Data Sheet'!C59 -> 52484.37 | D6: ='Data Sheet'!D59 -> 52834.81 | E6: ='Data Sheet'!E59 -> 46979.7 | F6: ='Data Sheet'!F59 -> 55198.76 | G6: ='Data Sheet'!G59 -> 52411.27 | H6: ='Data Sheet'!H59 -> 49144.98 | I6: ='Data Sheet'!I59 -> 42349.53 | ... K6: ='Data Sheet'!K59 -> 39494.87
A7: Other Liabilities | B7: ='Data Sheet'!B60 -> 15597.03 | C7: ='Data Sheet'!C60 -> 16027.12 | D7: ='Data Sheet'!D60 -> 15803.93 | E7: ='Data Sheet'!E60 -> 13292.61 | F7: ='Data Sheet'!F60 -> 13345.8 | G7: ='Data Sheet'!G60 -> 13011.61 | H7: ='Data Sheet'!H60 -> 14379.15 | I7: ='Data Sheet'!I60 -> 13596.08 | ... K7: ='Data Sheet'!K60 -> 17075.61
A8: Total | B8: ='Data Sheet'!B61 -> 75794.21 | C8: ='Data Sheet'!C61 -> 71511.05 | D8: ='Data Sheet'!D61 -> 69528.07 | E8: ='Data Sheet'!E61 -> 67984.6 | F8: ='Data Sheet'!F61 -> 75025 | G8: ='Data Sheet'!G61 -> 78535.47 | H8: ='Data Sheet'!H61 -> 81981.02 | I8: ='Data Sheet'!I61 -> 85821.27 | ... K8: ='Data Sheet'!K61 -> 112917.57
A10: Net Block | B10: ='Data Sheet'!B62 -> 56941.22 | C10: ='Data Sheet'!C62 -> 54390.93 | D10: ='Data Sheet'!D62 -> 52137.14 | E10: ='Data Sheet'!E62 -> 50418.76 | F10: ='Data Sheet'!F62 -> 55845.81 | G10: ='Data Sheet'!G62 -> 52851.3 | H10: ='Data Sheet'!H62 -> 53274.21 | I10: ='Data Sheet'!I62 -> 51451.38 | ... K10: ='Data Sheet'!K62 -> 69297.45
A11: Capital Work in Progress | B11: ='Data Sheet'!B63 -> 87.92 | C11: ='Data Sheet'!C63 -> 124.61 | D11: ='Data Sheet'!D63 -> 119.86 | E11: ='Data Sheet'!E63 -> 350.08 | F11: ='Data Sheet'!F63 -> 2346.77 | G11: ='Data Sheet'!G63 -> 6439.42 | H11: ='Data Sheet'!H63 -> 10269.74 | I11: ='Data Sheet'!I63 -> 12879.54 | ... K11: ='Data Sheet'!K63 -> 12104.42
A12: Investments | B12: ='Data Sheet'!B64 -> 0.06 | C12: ='Data Sheet'!C64 -> 164.33 | D12: ='Data Sheet'!D64 -> 0.01 | E12: ='Data Sheet'!E64 -> 2.72 | F12: ='Data Sheet'!F64 -> 2.8 | G12: ='Data Sheet'!G64 -> 20.1 | H12: ='Data Sheet'!H64 -> 183.25 | I12: ='Data Sheet'!I64 -> 654.05 | ... K12: ='Data Sheet'!K64 -> 1097.21
A13: Other Assets | B13: ='Data Sheet'!B65 -> 18765.01 | C13: ='Data Sheet'!C65 -> 16831.18 | D13: ='Data Sheet'!D65 -> 17271.06 | E13: ='Data Sheet'!E65 -> 17213.04 | F13: ='Data Sheet'!F65 -> 16829.62 | G13: ='Data Sheet'!G65 -> 19224.65 | H13: ='Data Sheet'!H65 -> 18253.82 | I13: ='Data Sheet'!I65 -> 20836.3 | ... K13: ='Data Sheet'!K65 -> 30418.49
A14: Total | B14: ='Data Sheet'!B66 -> 75794.21 | C14: ='Data Sheet'!C66 -> 71511.05 | D14: ='Data Sheet'!D66 -> 69528.07 | E14: ='Data Sheet'!E66 -> 67984.6 | F14: ='Data Sheet'!F66 -> 75025 | G14: ='Data Sheet'!G66 -> 78535.47 | H14: ='Data Sheet'!H66 -> 81981.02 | I14: ='Data Sheet'!I66 -> 85821.27 | ... K14: ='Data Sheet'!K66 -> 112917.57
A16: Working Capital | B16: =B13-B7 -> 3167.98 | C16: =C13-C7 -> 804.06 | D16: =D13-D7 -> 1467.13 | E16: =E13-E7 -> 3920.43 | F16: =F13-F7 -> 3483.82 | G16: =G13-G7 -> 6213.04 | H16: =H13-H7 -> 3874.67 | I16: =I13-I7 -> 7240.22 | ... K16: =K13-K7 -> 13342.88
A17: Debtors | B17: ='Data Sheet'!B67 -> 12476.6 | C17: ='Data Sheet'!C67 -> 7704.34 | D17: ='Data Sheet'!D67 -> 6069.81 | E17: ='Data Sheet'!E67 -> 8550.99 | F17: ='Data Sheet'!F67 -> 8366.47 | G17: ='Data Sheet'!G67 -> 11437.92 | H17: ='Data Sheet'!H67 -> 9560.92 | I17: ='Data Sheet'!I67 -> 11529.36 | ... K17: ='Data Sheet'!K67 -> 13022.07
A18: Inventory | B18: ='Data Sheet'!B68 -> 1619.2 | C18: ='Data Sheet'!C68 -> 1760.41 | D18: ='Data Sheet'!D68 -> 873.98 | E18: ='Data Sheet'!E68 -> 1224.08 | F18: ='Data Sheet'!F68 -> 2522.77 | G18: ='Data Sheet'!G68 -> 2025.11 | H18: ='Data Sheet'!H68 -> 2258.27 | I18: ='Data Sheet'!I68 -> 3075.2 | ... K18: ='Data Sheet'!K68 -> 3317.28
A20: Debtor Days | B20: =IF('Profit & Loss'!B4>0,'Balance Sheet'!B17/('Profit & Loss'!B4/365),0) -> 179.44989 | C20: =IF('Profit & Loss'!C4>0,'Balance Sheet'!C17/('Profit & Loss'!C4/365),0) -> 124.34317 | D20: =IF('Profit & Loss'!D4>0,'Balance Sheet'!D17/('Profit & Loss'!D4/365),0) -> 109.11397 | E20: =IF('Profit & Loss'!E4>0,'Balance Sheet'!E17/('Profit & Loss'!E4/365),0) -> 130.67693 | F20: =IF('Profit & Loss'!F4>0,'Balance Sheet'!F17/('Profit & Loss'!F4/365),0) -> 115.37683 | G20: =IF('Profit & Loss'!G4>0,'Balance Sheet'!G17/('Profit & Loss'!G4/365),0) -> 159.21454 | H20: =IF('Profit & Loss'!H4>0,'Balance Sheet'!H17/('Profit & Loss'!H4/365),0) -> 125.93241 | I20: =IF('Profit & Loss'!I4>0,'Balance Sheet'!I17/('Profit & Loss'!I4/365),0) -> 108.53387 | ... K20: =IF('Profit & Loss'!K4>0,'Balance Sheet'!K17/('Profit & Loss'!K4/365),0) -> 84.569292
A21: Inventory Turnover | B21: =IF('Balance Sheet'!B18>0,'Profit & Loss'!B4/'Balance Sheet'!B18,0) -> 15.672758 | C21: =IF('Balance Sheet'!C18>0,'Profit & Loss'!C4/'Balance Sheet'!C18,0) -> 12.846729 | D21: =IF('Balance Sheet'!D18>0,'Profit & Loss'!D4/'Balance Sheet'!D18,0) -> 23.231973 | E21: =IF('Balance Sheet'!E18>0,'Profit & Loss'!E4/'Balance Sheet'!E18,0) -> 19.511944 | F21: =IF('Balance Sheet'!F18>0,'Profit & Loss'!F4/'Balance Sheet'!F18,0) -> 10.491531 | G21: =IF('Balance Sheet'!G18>0,'Profit & Loss'!G4/'Balance Sheet'!G18,0) -> 12.948176 | H21: =IF('Balance Sheet'!H18>0,'Profit & Loss'!H4/'Balance Sheet'!H18,0) -> 12.270977 | I21: =IF('Balance Sheet'!I18>0,'Profit & Loss'!I4/'Balance Sheet'!I18,0) -> 12.608383 | ... K21: =IF('Balance Sheet'!K18>0,'Profit & Loss'!K4/'Balance Sheet'!K18,0) -> 16.942522
A23: Return on Equity | B23: =IF(SUM('Balance Sheet'!B4:B5)>0,'Profit & Loss'!B12/SUM('Balance Sheet'!B4:B5),"") -> 0.073756069 | C23: =IF(SUM('Balance Sheet'!C4:C5)>0,'Profit & Loss'!C12/SUM('Balance Sheet'!C4:C5),"") -> -2.0583352 | D23: =IF(SUM('Balance Sheet'!D4:D5)>0,'Profit & Loss'!D12/SUM('Balance Sheet'!D4:D5),"") -> -2.3646453 | E23: =IF(SUM('Balance Sheet'!E4:E5)>0,'Profit & Loss'!E12/SUM('Balance Sheet'!E4:E5),"") -> -0.12764043 | F23: =IF(SUM('Balance Sheet'!F4:F5)>0,'Profit & Loss'!F12/SUM('Balance Sheet'!F4:F5),"") -> -0.35102092 | G23: =IF(SUM('Balance Sheet'!G4:G5)>0,'Profit & Loss'!G12/SUM('Balance Sheet'!G4:G5),"") -> 0.096851957 | H23: =IF(SUM('Balance Sheet'!H4:H5)>0,'Profit & Loss'!H12/SUM('Balance Sheet'!H4:H5),"") -> 0.26611092 | I23: =IF(SUM('Balance Sheet'!I4:I5)>0,'Profit & Loss'!I12/SUM('Balance Sheet'!I4:I5),"") -> 0.35904278 | ... K23: =IF(SUM('Balance Sheet'!K4:K5)>0,'Profit & Loss'!K12/SUM('Balance Sheet'!K4:K5),"") -> 0.22962623
A24: Return on Capital Emp | C24: =IF((B4+B5+B6+C4+C5+C6)>0,('Profit & Loss'!C10+'Profit & Loss'!C9)*2/(B4+B5+B6+C4+C5+C6),"") -> -0.006197036 | D24: =IF((C4+C5+C6+D4+D5+D6)>0,('Profit & Loss'!D10+'Profit & Loss'!D9)*2/(C4+C5+C6+D4+D5+D6),"") -> 0.063938681 | E24: =IF((D4+D5+D6+E4+E5+E6)>0,('Profit & Loss'!E10+'Profit & Loss'!E9)*2/(D4+D5+D6+E4+E5+E6),"") -> 0.086346192 | F24: =IF((E4+E5+E6+F4+F5+F6)>0,('Profit & Loss'!F10+'Profit & Loss'!F9)*2/(E4+E5+E6+F4+F5+F6),"") -> 0.052416754 | G24: =IF((F4+F5+F6+G4+G5+G6)>0,('Profit & Loss'!G10+'Profit & Loss'!G9)*2/(F4+F5+F6+G4+G5+G6),"") -> 0.11627189 | H24: =IF((G4+G5+G6+H4+H5+H6)>0,('Profit & Loss'!H10+'Profit & Loss'!H9)*2/(G4+G5+G6+H4+H5+H6),"") -> 0.16032829 | I24: =IF((H4+H5+H6+I4+I5+I6)>0,('Profit & Loss'!I10+'Profit & Loss'!I9)*2/(H4+H5+H6+I4+I5+I6),"") -> 0.1574545 | J24: =IF((I4+I5+I6+J4+J5+J6)>0,('Profit & Loss'!J10+'Profit & Loss'!J9)*2/(I4+I5+I6+J4+J5+J6),"") -> 0.32242523 | K24: =IF((J4+J5+J6+K4+K5+K6)>0,('Profit & Loss'!K10+'Profit & Loss'!K9)*2/(J4+J5+J6+K4+K5+K6),"") -> 0.22694713

Sheet Cash Flow
A1: ='Balance Sheet'!A1 -> ADANI POWER LTD | E1: =UPDATE | J1: SCREENER.IN
A3: Narration | B3: ='Data Sheet'!B81 -> 42460 | C3: ='Data Sheet'!C81 -> 42825 | D3: ='Data Sheet'!D81 -> 43190 | E3: ='Data Sheet'!E81 -> 43555 | F3: ='Data Sheet'!F81 -> 43921 | G3: ='Data Sheet'!G81 -> 44286 | H3: ='Data Sheet'!H81 -> 44651 | I3: ='Data Sheet'!I81 -> 45016 | ... K3: ='Data Sheet'!K81 -> 45747
A4: Cash from Operating Activity | B4: ='Data Sheet'!B82 -> 5257.21 | C4: ='Data Sheet'!C82 -> 4725.2 | D4: ='Data Sheet'!D82 -> 5101.15 | E4: ='Data Sheet'!E82 -> 5610.38 | F4: ='Data Sheet'!F82 -> 5597.55 | G4: ='Data Sheet'!G82 -> 7014.35 | H4: ='Data Sheet'!H82 -> 10232.73 | I4: ='Data Sheet'!I82 -> 8430.53 | ... K4: ='Data Sheet'!K82 -> 21501.11
A5: Cash from Investing Activity | B5: ='Data Sheet'!B83 -> -2692.11 | C5: ='Data Sheet'!C83 -> -1212.04 | D5: ='Data Sheet'!D83 -> -520.43 | E5: ='Data Sheet'!E83 -> -984.02 | F5: ='Data Sheet'!F83 -> -2303.81 | G5: ='Data Sheet'!G83 -> -2187.57 | H5: ='Data Sheet'!H83 -> 774.46 | I5: ='Data Sheet'!I83 -> 1544.79 | ... K5: ='Data Sheet'!K83 -> -17142.05
A6: Cash from Financing Activity | B6: ='Data Sheet'!B84 -> -2712.95 | C6: ='Data Sheet'!C84 -> -3538.93 | D6: ='Data Sheet'!D84 -> -4600.11 | E6: ='Data Sheet'!E84 -> -4663.44 | F6: ='Data Sheet'!F84 -> -2377.18 | G6: ='Data Sheet'!G84 -> -5654.84 | H6: ='Data Sheet'!H84 -> -10337.86 | I6: ='Data Sheet'!I84 -> -10408.46 | ... K6: ='Data Sheet'!K84 -> -5175.45
A7: Net Cash Flow | B7: ='Data Sheet'!B85 -> -147.85 | C7: ='Data Sheet'!C85 -> -25.77 | D7: ='Data Sheet'!D85 -> -19.39 | E7: ='Data Sheet'!E85 -> -37.08 | F7: ='Data Sheet'!F85 -> 916.56 | G7: ='Data Sheet'!G85 -> -828.06 | H7: ='Data Sheet'!H85 -> 669.33 | I7: ='Data Sheet'!I85 -> -433.14 | ... K7: ='Data Sheet'!K85 -> -816.39

Sheet Customization
A1: How to use it?
A3: You can customize this workbook as you want.
B4: You can add custom formating, add conditional formating, add your own formulas… do ANYTHING.
B5: Please don't edit the "Data Sheet" only.
A7: After customization, you can upload this back on Screener.
B8: Upload on: | C8: https://www.screener.in/excel/
A10: Download your customized workbooks now onwards.
B11: Now whenever you will "Export to excel" from Screener, it will export your customized file.
A14: TESTING:
B15: This is a testing feature currently.
B16: You can report any formula errors on the worksheet at: support@screener.in

Sheet Data Sheet
A1: COMPANY NAME | B1: ADANI POWER LTD | E1: =IF(B2<>B3, "A NEW VERSION OF THE WORKSHEET IS AVAILABLE", "")
A2: LATEST VERSION | B2: 2.1 | E2: PLEASE DO NOT MAKE ANY CHANGES TO THIS SHEET
A3: CURRENT VERSION | B3: 2.1
A5: META
A6: Number of shares | B6: =IF(B9>0, B9/B8, 0) -> 1928.4695
A7: Face Value | B7: 2
A8: Current Price | B8: 198.5
A9: Market Capitalization | B9: 382801.19
A15: PROFIT & LOSS
A16: Report Date | B16: 42460 | C16: 42825 | D16: 43190 | E16: 43555 | F16: 43921 | G16: 44286 | H16: 44651 | I16: 45016 | J16: 45382 | K16: 45747
A17: Sales | B17: 25377.33 | C17: 22615.51 | D17: 20304.28 | E17: 23884.18 | F17: 26467.72 | G17: 26221.48 | H17: 27711.18 | I17: 38773.3 | J17: 50351.25 | K17: 56203.09
A18: Raw Material Cost
A19: Change in Inventory
A20: Power and Fuel | B20: 14745.14 | C20: 14630.49 | D20: 12535.25 | E20: 15952.45 | F20: 17580.39 | G20: 14781.15 | H20: 14762.21 | I20: 25480.85 | J20: 28452.64 | K20: 30273.25
A21: Other Mfr. Exp | B21: 1025.25 | C21: 1260.02 | D21: 1551.86 | E21: 1680.59 | F21: 1864.95 | G21: 1838.18 | H21: 2066.68 | I21: 1718.27 | J21: 1856.84 | K21: 2231.05
A22: Employee Cost | B22: 378.89 | C22: 361.01 | D22: 353.9 | E22: 363.47 | F22: 427.04 | G22: 431.89 | H22: 470.72 | I22: 570.46 | J22: 644.17 | K22: 786.63
A23: Selling and admin | B23: 509.04 | C23: 307.25 | D23: 225.3 | E23: 222.73 | F23: 454.63 | G23: 281.14 | H23: 233.67 | I23: 443.65 | J23: 454.82 | K23: 543.57
A24: Other Expenses | B24: -83.12 | C24: 76.7 | D24: 202.04 | E24: 681.53 | F24: 407.07 | G24: 200.96 | H24: 296.49 | I24: 463.73 | J24: 715.16 | K24: 950.26
A25: Other Income | B25: -201.37 | C25: -3666.12 | D25: 754.1 | E25: 2447.87 | F25: 322.76 | G25: 1908.56 | H25: 3908.04 | I25: 4215.54 | J25: 9883.31 | K25: 2589.85
A26: Depreciation | B26: 2665.82 | C26: 2672.36 | D26: 2698.72 | E26: 2750.62 | F26: 3006.5 | G26: 3201.65 | H26: 3117.54 | I26: 3303.68 | J26: 3931.33 | K26: 4308.88
A27: Interest | B27: 5560.22 | C27: 5901.73 | D27: 5570.23 | E27: 5656.52 | F27: 5314.82 | G27: 5106.33 | H27: 4094.78 | I27: 3333.5 | J27: 3388.09 | K27: 3339.79
A28: Profit before tax | B28: 374.72 | C28: -6260.17 | D28: -2078.92 | E28: -975.86 | F28: -2264.92 | G28: 2288.74 | H28: 6577.13 | I28: 7674.7 | J28: 20791.51 | K28: 16359.51
A29: Tax | B29: -176.08 | C29: -86.07 | D29: -5.15 | E29: 8.54 | F29: 9.85 | G29: 1018.76 | H29: 1665.55 | I29: -3051.94 | J29: -37.28 | K29: 3609.9
A30: Net profit | B30: 550.8 | C30: -6174.1 | D30: -2102.95 | E30: -984.4 | F30: -2274.77 | G30: 1269.98 | H30: 4911.58 | I30: 10726.64 | J30: 20828.79 | K30: 12938.77
A31: Dividend Amount
A40: Quarters
A41: Report Date | B41: 45199 | C41: 45291 | D41: 45382 | E41: 45473 | F41: 45565 | G41: 45657 | H41: 45747 | I41: 45838 | J41: 45930 | K41: 46022
A42: Sales | B42: 12990.58 | C42: 12991.44 | D42: 13363.69 | E42: 14955.63 | F42: 13338.88 | G42: 13671.18 | H42: 14237.4 | I42: 14109.15 | J42: 13456.84 | K42: 12451.44
A43: Expenses | B43: 7819.19 | C43: 8346.1 | D43: 8513.95 | E43: 8761.32 | F43: 8063.3 | G43: 8648.26 | H43: 9424.77 | I43: 8423.87 | J43: 8306.55 | K43: 8213.37
A44: Other Income | B44: 1945.1 | C44: 363.83 | D44: 517.83 | E44: 518.32 | F44: 723.96 | G44: 1162.26 | H44: 298.2 | I44: 464.55 | J44: 850.95 | K44: 543.26
A45: Depreciation | B45: 1004.48 | C45: 1002.23 | D45: 990.03 | E45: 995.63 | F45: 1058.59 | G45: 1170.01 | H45: 1084.65 | I45: 1088.59 | J45: 1193.41 | K45: 1135.3
A46: Interest | B46: 888.44 | C46: 796.56 | D46: 819.6 | E46: 811.49 | F46: 806.87 | G46: 956.53 | H46: 764.9 | I46: 856.93 | J46: 841.63 | K46: 701.01
A47: Profit before tax | B47: 5223.57 | C47: 3210.38 | D47: 3557.94 | E47: 4905.51 | F47: 4134.08 | G47: 4058.64 | H47: 3261.28 | I47: 4204.31 | J47: 3966.2 | K47: 2945.02
A48: Tax | B48: -1370.6 | C48: 472.42 | D48: 820.7 | E48: 992.72 | F48: 836.56 | G48: 1118.57 | H48: 662.05 | I48: 899.18 | J48: 1059.74 | K48: 456.93
A49: Net profit | B49: 6594.17 | C49: 2737.96 | D49: 2737.24 | E49: 3912.79 | F49: 3331.8 | G49: 3057.21 | H49: 2636.97 | I49: 3384.86 | J49: 2952.78 | K49: 2479.58
A50: Operating Profit | B50: 5171.39 | C50: 4645.34 | D50: 4849.74 | E50: 6194.31 | F50: 5275.58 | G50: 5022.92 | H50: 4812.63 | I50: 5685.28 | J50: 5150.29 | K50: 4238.07
A55: BALANCE SHEET
A56: Report Date | B56: 42460 | C56: 42825 | D56: 43190 | E56: 43555 | F56: 43921 | G56: 44286 | H56: 44651 | I56: 45016 | J56: 45382 | K56: 45747
A57: Equity Share Capital | B57: 3333.94 | C57: 3856.94 | D57: 3856.94 | E57: 3856.94 | F57: 3856.94 | G57: 3856.94 | H57: 3856.94 | I57: 3856.94 | J57: 3856.94 | K57: 3856.94
A58: Reserves | B58: 4133.92 | C58: -857.38 | D58: -2967.61 | E58: 3855.35 | F58: 2623.5 | G58: 9255.65 | H58: 14599.95 | I58: 26018.72 | J58: 39041.54 | K58: 52490.15
...

Sheet P&L
A1: Report Date | B1: 42460 | C1: 42825 | D1: 43190 | E1: 43555 | F1: 43921 | G1: 44286 | H1: 44651 | I1: 45016 | J1: 45382 | K1: 45747
A2: Sales | B2: 25377.33 | C2: 22615.51 | D2: 20304.28 | E2: 23884.18 | F2: 26467.72 | G2: 26221.48 | H2: 27711.18 | I2: 38773.3 | J2: 50351.25 | K2: 56203.09
A3: Raw Material Cost
A4: Change in Inventory
A5: Power and Fuel | B5: 14745.14 | C5: 14630.49 | D5: 12535.25 | E5: 15952.45 | F5: 17580.39 | G5: 14781.15 | H5: 14762.21 | I5: 25480.85 | J5: 28452.64 | K5: 30273.25
A6: Other Mfr. Exp | B6: 1025.25 | C6: 1260.02 | D6: 1551.86 | E6: 1680.59 | F6: 1864.95 | G6: 1838.18 | H6: 2066.68 | I6: 1718.27 | J6: 1856.84 | K6: 2231.05
A7: Employee Cost | B7: 378.89 | C7: 361.01 | D7: 353.9 | E7: 363.47 | F7: 427.04 | G7: 431.89 | H7: 470.72 | I7: 570.46 | J7: 644.17 | K7: 786.63
A8: Selling and admin | B8: 509.04 | C8: 307.25 | D8: 225.3 | E8: 222.73 | F8: 454.63 | G8: 281.14 | H8: 233.67 | I8: 443.65 | J8: 454.82 | K8: 543.57
A9: Other Expenses | B9: -83.12 | C9: 76.7 | D9: 202.04 | E9: 681.53 | F9: 407.07 | G9: 200.96 | H9: 296.49 | I9: 463.73 | J9: 715.16 | K9: 950.26
A10: Other Income | B10: -201.37 | C10: -3666.12 | D10: 754.1 | E10: 2447.87 | F10: 322.76 | G10: 1908.56 | H10: 3908.04 | I10: 4215.54 | J10: 9883.31 | K10: 2589.85
A11: Depreciation | B11: 2665.82 | C11: 2672.36 | D11: 2698.72 | E11: 2750.62 | F11: 3006.5 | G11: 3201.65 | H11: 3117.54 | I11: 3303.68 | J11: 3931.33 | K11: 4308.88
A12: Interest | B12: 5560.22 | C12: 5901.73 | D12: 5570.23 | E12: 5656.52 | F12: 5314.82 | G12: 5106.33 | H12: 4094.78 | I12: 3333.5 | J12: 3388.09 | K12: 3339.79
A13: Profit before tax | B13: 374.72 | C13: -6260.17 | D13: -2078.92 | E13: -975.86 | F13: -2264.92 | G13: 2288.74 | H13: 6577.13 | I13: 7674.7 | J13: 20791.51 | K13: 16359.51
A14: Tax | B14: -176.08 | C14: -86.07 | D14: -5.15 | E14: 8.54 | F14: 9.85 | G14: 1018.76 | H14: 1665.55 | I14: -3051.94 | J14: -37.28 | K14: 3609.9
A15: Net profit | B15: 550.8 | C15: -6174.1 | D15: -2102.95 | E15: -984.4 | F15: -2274.77 | G15: 1269.98 | H15: 4911.58 | I15: 10726.64 | J15: 20828.79 | K15: 12938.77

Sheet -quat
A1: Narration | B1: 42430 | C1: 42795 | D1: 43160 | E1: 43525 | F1: 43891 | G1: 44256 | H1: 44621 | I1: 44986 | J1: 45352 | K1: 45717
A2: Sales | B2: 12991 | C2: 12300 | D2: 13363.66 | E2: 14998.66 | F2: 13488 | G2: 13681 | H2: 14247 | I2: 14109.15 | J2: 13456.4 | K2: 12451.44
A3: Expenses | B3: ='Data Sheet'!B41 -> 45199 | C3: ='Data Sheet'!C41 -> 45291 | D3: ='Data Sheet'!D41 -> 45382 | E3: ='Data Sheet'!E41 -> 45473 | F3: ='Data Sheet'!F41 -> 45565 | G3: ='Data Sheet'!G41 -> 45657 | H3: ='Data Sheet'!H41 -> 45747 | I3: ='Data Sheet'!I41 -> 45838 | ... K3: ='Data Sheet'!K41 -> 46022
A4: Operating Profit | B4: ='Data Sheet'!B48 -> -1370.6 | C4: ='Data Sheet'!C48 -> 472.42 | D4: ='Data Sheet'!D48 -> 820.7 | E4: ='Data Sheet'!E48 -> 992.72 | F4: ='Data Sheet'!F48 -> 836.56 | G4: ='Data Sheet'!G48 -> 1118.57 | H4: ='Data Sheet'!H48 -> 662.05 | I4: ='Data Sheet'!I48 -> 899.18 | ... K4: ='Data Sheet'!K48 -> 456.93
A5: Other Income | B5: ='Data Sheet'!B42 -> 12990.58 | C5: ='Data Sheet'!C42 -> 12991.44 | D5: ='Data Sheet'!D42 -> 13363.69 | E5: ='Data Sheet'!E42 -> 14955.63 | F5: ='Data Sheet'!F42 -> 13338.88 | G5: ='Data Sheet'!G42 -> 13671.18 | H5: ='Data Sheet'!H42 -> 14237.4 | I5: ='Data Sheet'!I42 -> 14109.15 | ... K5: ='Data Sheet'!K42 -> 12451.44
A6: Depreciation | B6: ='Data Sheet'!B43 -> 7819.19 | C6: ='Data Sheet'!C43 -> 8346.1 | D6: ='Data Sheet'!D43 -> 8513.95 | E6: ='Data Sheet'!E43 -> 8761.32 | F6: ='Data Sheet'!F43 -> 8063.3 | G6: ='Data Sheet'!G43 -> 8648.26 | H6: ='Data Sheet'!H43 -> 9424.77 | I6: ='Data Sheet'!I43 -> 8423.87 | ... K6: ='Data Sheet'!K43 -> 8213.37
A7: Interest | B7: ='Data Sheet'!B44 -> 1945.1 | C7: ='Data Sheet'!C44 -> 363.83 | D7: ='Data Sheet'!D44 -> 517.83 | E7: ='Data Sheet'!E44 -> 518.32 | F7: ='Data Sheet'!F44 -> 723.96 | G7: ='Data Sheet'!G44 -> 1162.26 | H7: ='Data Sheet'!H44 -> 298.2 | I7: ='Data Sheet'!I44 -> 464.55 | ... K7: ='Data Sheet'!K44 -> 543.26
A8: Profit before tax | B8: ='Data Sheet'!B45 -> 1004.48 | C8: ='Data Sheet'!C45 -> 1002.23 | D8: ='Data Sheet'!D45 -> 990.03 | E8: ='Data Sheet'!E45 -> 995.63 | F8: ='Data Sheet'!F45 -> 1058.59 | G8: ='Data Sheet'!G45 -> 1170.01 | H8: ='Data Sheet'!H45 -> 1084.65 | I8: ='Data Sheet'!I45 -> 1088.59 | ... K8: ='Data Sheet'!K45 -> 1135.3
A9: Tax | B9: ='Data Sheet'!B46 -> 888.44 | C9: ='Data Sheet'!C46 -> 796.56 | D9: ='Data Sheet'!D46 -> 819.6 | E9: ='Data Sheet'!E46 -> 811.49 | F9: ='Data Sheet'!F46 -> 806.87 | G9: ='Data Sheet'!G46 -> 956.53 | H9: ='Data Sheet'!H46 -> 764.9 | I9: ='Data Sheet'!I46 -> 856.93 | ... K9: ='Data Sheet'!K46 -> 701.01
A10: Net profit | B10: ='Data Sheet'!B47 -> 5223.57 | C10: ='Data Sheet'!C47 -> 3210.38 | D10: ='Data Sheet'!D47 -> 3557.94 | E10: ='Data Sheet'!E47 -> 4905.51 | F10: ='Data Sheet'!F47 -> 4134.08 | G10: ='Data Sheet'!G47 -> 4058.64 | H10: ='Data Sheet'!H47 -> 3261.28 | I10: ='Data Sheet'!I47 -> 4204.31 | ... K10: ='Data Sheet'!K47 -> 2945.02
A12: OPM | B12: =IF(B2>0,B4/B2,"") -> -0.10550381 | C12: =IF(C2>0,C4/C2,"") -> 0.03840813 | D12: =IF(D2>0,D4/D2,"") -> 0.061412817 | E12: =IF(E2>0,E4/E2,"") -> 0.066187246 | F12: =IF(F2>0,F4/F2,"") -> 0.062022539 | G12: =IF(G2>0,G4/G2,"") -> 0.081760836 | H12: =IF(H2>0,H4/H2,"") -> 0.046469432 | I12: =IF(I2>0,I4/I2,"") -> 0.063730274 | ... K12: =IF(K2>0,K4/K2,"") -> 0.03669696

Sheet bs
A1: Narration | B1: 42430 | C1: 42795 | D1: 43160 | E1: 43525 | F1: 43891 | G1: 44256 | H1: 44621 | I1: 44986 | J1: 45352 | K1: 45717
A2: Equity Share Capital | B2: ='Data Sheet'!B55 -> 0 | C2: ='Data Sheet'!C55 -> 0 | D2: ='Data Sheet'!D55 -> 0 | E2: ='Data Sheet'!E55 -> 0 | F2: ='Data Sheet'!F55 -> 0 | G2: ='Data Sheet'!G55 -> 0 | H2: ='Data Sheet'!H55 -> 0 | I2: ='Data Sheet'!I55 -> 0 | ... K2: ='Data Sheet'!K55 -> 0
A3: Reserves | B3: ='Data Sheet'!B56 -> 42460 | C3: ='Data Sheet'!C56 -> 42825 | D3: ='Data Sheet'!D56 -> 43190 | E3: ='Data Sheet'!E56 -> 43555 | F3: ='Data Sheet'!F56 -> 43921 | G3: ='Data Sheet'!G56 -> 44286 | H3: ='Data Sheet'!H56 -> 44651 | I3: ='Data Sheet'!I56 -> 45016 | ... K3: ='Data Sheet'!K56 -> 45747
A4: Borrowings | B4: ='Data Sheet'!B57 -> 3333.94 | C4: ='Data Sheet'!C57 -> 3856.94 | D4: ='Data Sheet'!D57 -> 3856.94 | E4: ='Data Sheet'!E57 -> 3856.94 | F4: ='Data Sheet'!F57 -> 3856.94 | G4: ='Data Sheet'!G57 -> 3856.94 | H4: ='Data Sheet'!H57 -> 3856.94 | I4: ='Data Sheet'!I57 -> 3856.94 | ... K4: ='Data Sheet'!K57 -> 3856.94
A5: Other Liabilities | B5: ='Data Sheet'!B58 -> 4133.92 | C5: ='Data Sheet'!C58 -> -857.38 | D5: ='Data Sheet'!D58 -> -2967.61 | E5: ='Data Sheet'!E58 -> 3855.35 | F5: ='Data Sheet'!F58 -> 2623.5 | G5: ='Data Sheet'!G58 -> 9255.65 | H5: ='Data Sheet'!H58 -> 14599.95 | I5: ='Data Sheet'!I58 -> 26018.72 | ... K5: ='Data Sheet'!K58 -> 52490.15
A6: Total | B6: ='Data Sheet'!B59 -> 52729.32 | C6: ='Data Sheet'!C59 -> 52484.37 | D6: ='Data Sheet'!D59 -> 52834.81 | E6: ='Data Sheet'!E59 -> 46979.7 | F6: ='Data Sheet'!F59 -> 55198.76 | G6: ='Data Sheet'!G59 -> 52411.27 | H6: ='Data Sheet'!H59 -> 49144.98 | I6: ='Data Sheet'!I59 -> 42349.53 | ... K6: ='Data Sheet'!K59 -> 39494.87
A8: Net Block | B8: ='Data Sheet'!B60 -> 15597.03 | C8: ='Data Sheet'!C60 -> 16027.12 | D8: ='Data Sheet'!D60 -> 15803.93 | E8: ='Data Sheet'!E60 -> 13292.61 | F8: ='Data Sheet'!F60 -> 13345.8 | G8: ='Data Sheet'!G60 -> 13011.61 | H8: ='Data Sheet'!H60 -> 14379.15 | I8: ='Data Sheet'!I60 -> 13596.08 | ... K8: ='Data Sheet'!K60 -> 17075.61
A9: Capital Work in Progress | B9: ='Data Sheet'!B61 -> 75794.21 | C9: ='Data Sheet'!C61 -> 71511.05 | D9: ='Data Sheet'!D61 -> 69528.07 | E9: ='Data Sheet'!E61 -> 67984.6 | F9: ='Data Sheet'!F61 -> 75025 | G9: ='Data Sheet'!G61 -> 78535.47 | H9: ='Data Sheet'!H61 -> 81981.02 | I9: ='Data Sheet'!I61 -> 85821.27 | ... K9: ='Data Sheet'!K61 -> 112917.57
A10: Investments | B10: ='Data Sheet'!B62 -> 56941.22 | C10: ='Data Sheet'!C62 -> 54390.93 | D10: ='Data Sheet'!D62 -> 52137.14 | E10: ='Data Sheet'!E62 -> 50418.76 | F10: ='Data Sheet'!F62 -> 55845.81 | G10: ='Data Sheet'!G62 -> 52851.3 | H10: ='Data Sheet'!H62 -> 53274.21 | I10: ='Data Sheet'!I62 -> 51451.38 | ... K10: ='Data Sheet'!K62 -> 69297.45
A11: Other Assets | B11: ='Data Sheet'!B63 -> 87.92 | C11: ='Data Sheet'!C63 -> 124.61 | D11: ='Data Sheet'!D63 -> 119.86 | E11: ='Data Sheet'!E63 -> 350.08 | F11: ='Data Sheet'!F63 -> 2346.77 | G11: ='Data Sheet'!G63 -> 6439.42 | H11: ='Data Sheet'!H63 -> 10269.74 | I11: ='Data Sheet'!I63 -> 12879.54 | ... K11: ='Data Sheet'!K63 -> 12104.42
A12: Total | B12: ='Data Sheet'!B64 -> 0.06 | C12: ='Data Sheet'!C64 -> 164.33 | D12: ='Data Sheet'!D64 -> 0.01 | E12: ='Data Sheet'!E64 -> 2.72 | F12: ='Data Sheet'!F64 -> 2.8 | G12: ='Data Sheet'!G64 -> 20.1 | H12: ='Data Sheet'!H64 -> 183.25 | I12: ='Data Sheet'!I64 -> 654.05 | ... K12: ='Data Sheet'!K64 -> 1097.21
A14: Working Capital | B14: =B11-B5 -> -4046 | C14: =C11-C5 -> 981.99 | D14: =D11-D5 -> 3087.47 | E14: =E11-E5 -> -3505.27 | F14: =F11-F5 -> -276.73 | G14: =G11-G5 -> -2816.23 | H14: =H11-H5 -> -4330.21 | I14: =I11-I5 -> -13139.18 | ... K14: =K11-K5 -> -40385.73
A15: Debtors | B15: ='Data Sheet'!B65 -> 18765.01 | C15: ='Data Sheet'!C65 -> 16831.18 | D15: ='Data Sheet'!D65 -> 17271.06 | E15: ='Data Sheet'!E65 -> 17213.04 | F15: ='Data Sheet'!F65 -> 16829.62 | G15: ='Data Sheet'!G65 -> 19224.65 | H15: ='Data Sheet'!H65 -> 18253.82 | I15: ='Data Sheet'!I65 -> 20836.3 | ... K15: ='Data Sheet'!K65 -> 30418.49
A16: Inventory | B16: ='Data Sheet'!B66 -> 75794.21 | C16: ='Data Sheet'!C66 -> 71511.05 | D16: ='Data Sheet'!D66 -> 69528.07 | E16: ='Data Sheet'!E66 -> 67984.6 | F16: ='Data Sheet'!F66 -> 75025 | G16: ='Data Sheet'!G66 -> 78535.47 | H16: ='Data Sheet'!H66 -> 81981.02 | I16: ='Data Sheet'!I66 -> 85821.27 | ... K16: ='Data Sheet'!K66 -> 112917.57
A18: Debtor Days | B18: 179.45 | C18: 124.34 | D18: 109.11 | E18: 130.66 | F18: 115.38 | G18: 159.21 | H18: 125.93 | I18: 108.52 | J18: 84.65 | K18: 84.57
A19: Inventory Turnover | B19: 15.67 | C19: 12.85 | D19: 16.23 | E19: 19.51 | F19: 10.49 | G19: 12.95 | H19: 12.27 | I19: 12.64 | J19: 12.16 | K19: 16.9
A21: Return on Equity | B21: =IF(SUM('Balance Sheet'!B2:B3)>0,'Profit & Loss'!B10/SUM('Balance Sheet'!B2:B3),"") -> 0.0088252473 | C21: =IF(SUM('Balance Sheet'!C2:C3)>0,'Profit & Loss'!C10/SUM('Balance Sheet'!C2:C3),"") -> -0.14618027 | D21: =IF(SUM('Balance Sheet'!D2:D3)>0,'Profit & Loss'!D10/SUM('Balance Sheet'!D2:D3),"") -> -0.04813429 | E21: =IF(SUM('Balance Sheet'!E2:E3)>0,'Profit & Loss'!E10/SUM('Balance Sheet'!E2:E3),"") -> -0.022405235 | F21: =IF(SUM('Balance Sheet'!F2:F3)>0,'Profit & Loss'!F10/SUM('Balance Sheet'!F2:F3),"") -> -0.051568043 | G21: =IF(SUM('Balance Sheet'!G2:G3)>0,'Profit & Loss'!G10/SUM('Balance Sheet'!G2:G3),"") -> 0.051680892 | H21: =IF(SUM('Balance Sheet'!H2:H3)>0,'Profit & Loss'!H10/SUM('Balance Sheet'!H2:H3),"") -> 0.14730084 | I21: =IF(SUM('Balance Sheet'!I2:I3)>0,'Profit & Loss'!I10/SUM('Balance Sheet'!I2:I3),"") -> 0.17048827 | ... K21: =IF(SUM('Balance Sheet'!K2:K3)>0,'Profit & Loss'!K10/SUM('Balance Sheet'!K2:K3),"") -> 0.35760837
A22: Return on Capital Emp | C22: =IF((B2+B3+B4+C2+C3+C4)>0,('Profit & Loss'!C8+'Profit & Loss'!C7)*2/(B2+B3+B4+C2+C3+C4),"") -> -0.021492307 | D22: =IF((C2+C3+C4+D2+D3+D4)>0,('Profit & Loss'!D8+'Profit & Loss'!D7)*2/(C2+C3+C4+D2+D3+D4),"") -> 0.073676758 | E22: =IF((D2+D3+D4+E2+E3+E4)>0,('Profit & Loss'!E8+'Profit & Loss'!E7)*2/(D2+D3+D4+E2+E3+E4),"") -> 0.11006885 | F22: =IF((E2+E3+E4+F2+F3+F4)>0,('Profit & Loss'!F8+'Profit & Loss'!F7)*2/(E2+E3+E4+F2+F3+F4),"") -> 0.069949873 | G22: =IF((F2+F3+F4+G2+G3+G4)>0,('Profit & Loss'!G8+'Profit & Loss'!G7)*2/(F2+F3+F4+G2+G3+G4),"") -> 0.10655052 | H22: =IF((G2+G3+G4+H2+H3+H4)>0,('Profit & Loss'!H8+'Profit & Loss'!H7)*2/(G2+G3+G4+H2+H3+H4),"") -> 0.14538057 | I22: =IF((H2+H3+H4+I2+I3+I4)>0,('Profit & Loss'!I8+'Profit & Loss'!I7)*2/(H2+H3+H4+I2+I3+I4),"") -> 0.15442908 | J22: =IF((I2+I3+I4+J2+J3+J4)>0,('Profit & Loss'!J8+'Profit & Loss'!J7)*2/(I2+I3+I4+J2+J3+J4),"") -> 0.28160993 | K22: =IF((J2+J3+J4+K2+K3+K4)>0,('Profit & Loss'!K8+'Profit & Loss'!K7)*2/(J2+J3+J4+K2+K3+K4),"") -> 0.13958982

Sheet cf
A1: Narration | B1: 42430 | C1: 42795 | D1: 43160 | E1: 43525 | F1: 43891 | G1: 44256 | H1: 44621 | I1: 44986 | J1: 45352 | K1: 45717
A2: Cash from Operating Activity | B2: 5257.21 | C2: 4726 | D2: 5101.15 | E2: 5610.38 | F2: 5597.55 | G2: 7014.45 | H2: 10232.7 | I2: 8430.55 | J2: 14170.5 | K2: 21501.11
A3: Cash from Investing Activity | B3: ='Data Sheet'!B81 -> 42460 | C3: ='Data Sheet'!C81 -> 42825 | D3: ='Data Sheet'!D81 -> 43190 | E3: ='Data Sheet'!E81 -> 43555 | F3: ='Data Sheet'!F81 -> 43921 | G3: ='Data Sheet'!G81 -> 44286 | H3: ='Data Sheet'!H81 -> 44651 | I3: ='Data Sheet'!I81 -> 45016 | ... K3: ='Data Sheet'!K81 -> 45747
A4: Cash from Financing Activity | B4: ='Data Sheet'!B82 -> 5257.21 | C4: ='Data Sheet'!C82 -> 4725.2 | D4: ='Data Sheet'!D82 -> 5101.15 | E4: ='Data Sheet'!E82 -> 5610.38 | F4: ='Data Sheet'!F82 -> 5597.55 | G4: ='Data Sheet'!G82 -> 7014.35 | H4: ='Data Sheet'!H82 -> 10232.73 | I4: ='Data Sheet'!I82 -> 8430.53 | ... K4: ='Data Sheet'!K82 -> 21501.11
A5: Net Cash Flow | B5: ='Data Sheet'!B83 -> -2692.11 | C5: ='Data Sheet'!C83 -> -1212.04 | D5: ='Data Sheet'!D83 -> -520.43 | E5: ='Data Sheet'!E83 -> -984.02 | F5: ='Data Sheet'!F83 -> -2303.81 | G5: ='Data Sheet'!G83 -> -2187.57 | H5: ='Data Sheet'!H83 -> 774.46 | I5: ='Data Sheet'!I83 -> 1544.79 | ... K5: ='Data Sheet'!K83 -> -17142.05
